Workbook

Sheet project
A1: property | B1: value | C1: notes
A2: project_name | B2: tigit-projecte-territorial | C2: Identitat estable del projecte
A3: chapter_snapshot | B3: 05 | C3: Fita de preparació de dades
A4: case_territory | B4: Tarragonès | C4: Cas de demostració; contrastar l'ortografia amb la font oficial
A5: territorial_unit | B5: municipi | C5: Una fila analítica per municipi
A6: reference_period | B6: 2021 | C6: Període representat per les dades de població i habitatge
A7: working_language | B7: ca | C7: El català és la llengua de treball
A8: spreadsheet_application | B8: LibreOffice Calc 24.2.7.2; validar també amb Excel abans de publicar | C8: Anotar Calc o Excel i la versió utilitzada
A9: regional_configuration | B9: Interfície catalana; decimal amb coma; fórmules OOXML en anglès al fitxer | C9: Anotar els separadors decimals i de fórmules
A10: author | B10: Equip docent TIGIT | C10: Completar abans de produir captures docents
A11: question | B11: Com es distribueixen la població i el parc d'habitatges entre els municipis? | C11: Pregunta descriptiva inicial

Sheet sources
A1: source_id | B1: producer | C1: title | D1: url | E1: reference_period | F1: access_date | G1: license | H1: format | I1: selection | J1: raw_file | K1: notes
A2: idescat_population_2021 | B2: Idescat | C2: Població. Per sexe i edat any a any | D2: https://api.idescat.cat/taules/v2/censph/10/5975/mun/data?lang=ca&YEAR=2021&MUN=430120,430430,430477,430509,430957,430976,431009,431037,431093,431114,431227,431264,431310,431359,431444,431482,431536,431649,431665,431711,439057,439076&SEX=TOTAL | E2: 2021 | F2: 2026-08-18 | G2: Condicions d'ús de l'API d'Idescat | H2: CSV UTF-8 derivat d'una consulta JSON-stat documentada | I2: Tarragonès; edats simples; total de tots els sexes | J2: poblacio-edat-tarragones-2021.csv | K2: La versió docent conserva també la consulta reproduïble de l'API
A3: idescat_housing_2021 | B3: Idescat | C3: Habitatges. Per tipus d'habitatge | D3: https://www.idescat.cat/pub/?id=censph&n=30&lang=ca&geo=mun&f=ssv | E3: 2021 | F3: 2026-08-18 | G3: Avís legal i condicions de reutilització d'Idescat | H3: CSV UTF-8; separador ; | I3: Tots els municipis | J3: t30mun.csv | K3: Revisar les notes de confidencialitat i arrodoniment
A4: idescat_codes | B4: Idescat | C4: Codis de municipis i comarques | D4: https://www.idescat.cat/codis/?id=50&n=9&lang=ca&f=ssv | E4: vigent en la data d'accés | F4: 2026-08-18 | G4: Avís legal i condicions de reutilització d'Idescat | H4: CSV UTF-8; separador ; | I4: Municipis i comarques | J4: mpiscatalunya.csv | K4: Els codis municipals s'han d'importar com a text
A5: idescat_surface | B5: Idescat | C5: Superfície, densitat i entitats singulars | D5: https://www.idescat.cat/pub/?id=inddt&n=396&lang=ca&geo=mun&f=ssv | E5: 2025 | F5: 2026-08-18 | G5: Avís legal i condicions de reutilització d'Idescat | H5: CSV UTF-8; separador ; | I5: Tots els municipis | J5: t396mun.csv | K5: Registrar el període o la data d'actualització de la taula

Sheet dictionary
A1: field | B1: sheet | C1: label | D1: type | E1: unit | F1: source_id | G1: missing_treatment | H1: definition | I1: question | J1: formula | K1: scale_factor | L1: intended_use | M1: limitations
A2: municipality_code | B2: municipal | C2: Codi de municipi | D2: text | F2: idescat_codes | G2: No substituir per zero | H2: Clau oficial de sis caràcters per a les unions
A3: municipality_name | B3: municipal | C3: Municipi | D3: text | F3: idescat_codes | G3: No substituir | H3: Nom oficial del municipi
A4: county_code | B4: municipal | C4: Codi de comarca | D4: text | F4: idescat_codes | G4: No substituir | H4: Clau utilitzada per filtrar el territori d'estudi
A5: county_name | B5: municipal | C5: Comarca | D5: text | F5: idescat_codes | G5: No substituir | H5: Nom oficial de la comarca
A6: population_total | B6: municipal | C6: Població total | D6: integer | E6: persones | F6: idescat_population_2021 | G6: Preservar absent | H6: Població resident durant el període de referència
A7: population_0_14 | B7: municipal | C7: Població de 0 a 14 anys | D7: integer | E7: persones | F7: idescat_population_2021 | G7: Preservar absent | H7: Població d'edats joves
A8: population_15_64 | B8: municipal | C8: Població de 15 a 64 anys | D8: integer | E8: persones | F8: idescat_population_2021 | G8: Preservar absent | H8: Interval d'edat central de la demostració
A9: population_65_plus | B9: municipal | C9: Població de 65 anys o més | D9: integer | E9: persones | F9: idescat_population_2021 | G9: Preservar absent | H9: Població d'edats avançades
A10: housing_total | B10: municipal | C10: Habitatges totals | D10: integer | E10: habitatges | F10: idescat_housing_2021 | G10: Preservar absent | H10: Parc total d'habitatges
A11: housing_main | B11: municipal | C11: Habitatges principals | D11: integer | E11: habitatges | F11: idescat_housing_2021 | G11: Preservar absent | H11: Habitatges principals
A12: housing_non_main | B12: municipal | C12: Habitatges no principals | D12: integer | E12: habitatges | F12: idescat_housing_2021 | G12: Preservar absent | H12: Habitatges d'ús ocasional i buits; no equivalen a habitatges turístics
A13: surface_km2 | B13: municipal | C13: Superfície | D13: decimal | E13: km² | F13: idescat_surface | G13: Preservar absent | H13: Superfície municipal que després actuarà com a denominador
A14: population_0_14_pct | B14: indicators_demography | C14: Pes de la població jove | D14: decimal | E14: % | F14: idescat_population_2021 | G14: NA si el total no és positiu | H14: Població de 0–14 sobre població total | I14: On pesa més la població jove? | J14: population_0_14 / population_total × 100 | K14: 100 | L14: Comparar estructura demogràfica | M14: No explica les causes de l'estructura
A15: population_65_plus_pct | B15: indicators_demography | C15: Pes de la població gran | D15: decimal | E15: % | F15: idescat_population_2021 | G15: NA si el total no és positiu | H15: Població de 65+ sobre població total | I15: On pesa més la població gran? | J15: population_65_plus / population_total × 100 | K15: 100 | L15: Comparar envelliment relatiu | M15: No mesura necessitats individuals
A16: ageing_index_per_100_young | B16: indicators_demography | C16: Índex d'envelliment | D16: decimal | E16: persones per 100 | F16: idescat_population_2021 | G16: NA si 0–14 no és positiu | H16: Relació entre població gran i jove | I16: Quina relació hi ha entre els extrems d'edat? | J16: population_65_plus / population_0_14 × 100 | K16: 100 | L16: Comparar estructura d'edats | M16: És sensible a denominadors petits
A17: population_density_hab_km2 | B17: indicators_demography | C17: Densitat de població | D17: decimal | E17: habitants/km² | F17: idescat_population_2021; idescat_surface | G17: NA si la superfície no és positiva | H17: Població per superfície municipal | I17: On es concentra la població? | J17: population_total / surface_km2 | K17: 1 | L17: Comparar concentració mitjana | M17: No descriu la distribució interna; superfície publicada el 2025
A18: housing_non_main_pct | B18: indicators_housing | C18: Pes de l'habitatge no principal | D18: decimal | E18: % | F18: idescat_housing_2021 | G18: NA si el total no és positiu | H18: Habitatge no principal sobre total | I18: On pesa més l'habitatge no principal? | J18: housing_non_main / housing_total × 100 | K18: 100 | L18: Comparar composició residencial | M18: No identifica habitatges turístics
A19: residents_per_housing_main | B19: indicators_housing | C19: Residents per habitatge principal | D19: decimal | E19: residents/habitatge | F19: idescat_population_2021; idescat_housing_2021 | G19: NA si habitatges principals no és positiu | H19: Població sobre habitatges principals | I19: Quina relació aproximada hi ha entre residents i parc principal? | J19: population_total / housing_main | K19: 1 | L19: Contextualitzar ocupació residencial | M19: No és la grandària oficial de la llar

Sheet source_codes
A1: Codi | B1: Nom | C1: Codi comarca | D1: Nom comarca
A2: 250019 | B2: Abella de la Conca | C2: 25 | D2: Pallars Jussà
A3: 080018 | B3: Abrera | C3: 11 | D3: Baix Llobregat
A4: 250024 | B4: Àger | C4: 23 | D4: Noguera
A5: 250030 | B5: Agramunt | C5: 38 | D5: Urgell
A6: 080023 | B6: Aguilar de Segarra | C6: 07 | D6: Bages
A7: 170010 | B7: Agullana | C7: 02 | D7: Alt Empordà
A8: 080142 | B8: Aiguafreda | C8: 24 | D8: Osona
A9: 430017 | B9: Aiguamúrcia | C9: 01 | D9: Alt Camp
A10: 170025 | B10: Aiguaviva | C10: 20 | D10: Gironès
A11: 250387 | B11: Aitona | C11: 33 | D11: Segrià
A12: 250045 | B12: Alamús, els | C12: 33 | D12: Segrià
... A948: 430521 | B948: Xerta | C948: 09 | D948: Baix Ebre

Sheet source_surface
A1: Codi | B1: Nom | C1: Superfície (km²) | D1: Densitat (hab./km²) | E1: Entitats singulars població (nombre)
A2: 250019 | B2: Abella de la Conca | C2: 78,27 | D2: 2,1 | E2: 5
A3: 080018 | B3: Abrera | C3: 19,94 | D3: 662,3 | E3: 2
A4: 250024 | B4: Àger | C4: 160,57 | D4: 4,0 | E4: 9
A5: 250030 | B5: Agramunt | C5: 79,65 | D5: 70,8 | E5: 6
A6: 080023 | B6: Aguilar de Segarra | C6: 43,32 | D6: 6,8 | E6: 3
A7: 170010 | B7: Agullana | C7: 27,73 | D7: 31,8 | E7: 2
A8: 080142 | B8: Aiguafreda | C8: 7,90 | D8: 325,2 | E8: 1
A9: 430017 | B9: Aiguamúrcia | C9: 72,95 | D9: 13,7 | E9: 9
A10: 170025 | B10: Aiguaviva | C10: 13,91 | D10: 57,9 | E10: 8
A11: 250387 | B11: Aitona | C11: 66,90 | D11: 38,5 | E11: 3
A12: 250045 | B12: Alamús, els | C12: 20,53 | D12: 40,8 | E12: 3
... A948: 430521 | B948: Xerta | C948: 32,39 | D948: 36,6 | E948: 1

Sheet source_population
A1: YEAR | B1: MUN | C1: AGE | D1: SEX | E1: CONCEPT | F1: value | G1: status
A2: 2021 | B2: 430120 | C2: Y000 | D2: TOTAL | E2: POP | F2: 40
A3: 2021 | B3: 430120 | C3: Y001 | D3: TOTAL | E3: POP | F3: 50
A4: 2021 | B4: 430120 | C4: Y002 | D4: TOTAL | E4: POP | F4: 44
A5: 2021 | B5: 430120 | C5: Y003 | D5: TOTAL | E5: POP | F5: 58
A6: 2021 | B6: 430120 | C6: Y004 | D6: TOTAL | E6: POP | F6: 73
A7: 2021 | B7: 430120 | C7: Y005 | D7: TOTAL | E7: POP | F7: 55
A8: 2021 | B8: 430120 | C8: Y006 | D8: TOTAL | E8: POP | F8: 68
A9: 2021 | B9: 430120 | C9: Y007 | D9: TOTAL | E9: POP | F9: 69
A10: 2021 | B10: 430120 | C10: Y008 | D10: TOTAL | E10: POP | F10: 68
A11: 2021 | B11: 430120 | C11: Y009 | D11: TOTAL | E11: POP | F11: 60
A12: 2021 | B12: 430120 | C12: Y010 | D12: TOTAL | E12: POP | F12: 81
A13: 2021 | B13: 430120 | C13: Y011 | D13: TOTAL | E13: POP | F13: 70
... A2245: 2021 | B2245: 431711 | C2245: TOTAL | D2245: TOTAL | E2245: POP | F2245: 22781

Sheet source_housing
A1: Codi | B1: Nom | C1: Habitatges familiars convencionals principals | D1: Habitatges familiars convencionals no principals | E1: Habitatges familiars convencionals | F1: Habitatges familiars no convencionals (allotjaments) | G1: Total habitatges familiars | H1: Establiments col·lectius
A2: 250019 | B2: Abella de la Conca | C2: 65 | D2: 52 | E2: 117 | F2: 0 | G2: 117 | H2: 0
A3: 080018 | B3: Abrera | C3: 4643 | D3: 623 | E3: 5266 | F3: 0 | G3: 5266 | H3: 5
A4: 250024 | B4: Àger | C4: 239 | D4: 453 | E4: 692 | F4: 0 | G4: 692 | H4: 1
A5: 250030 | B5: Agramunt | C5: 2049 | D5: 696 | E5: 2745 | F5: 0 | G5: 2745 | H5: 1
A6: 080023 | B6: Aguilar de Segarra | C6: 99 | D6: 52 | E6: 151 | F6: 0 | G6: 151 | H6: 0
A7: 170010 | B7: Agullana | C7: 350 | D7: 239 | E7: 589 | F7: 0 | G7: 589 | H7: 0
A8: 080142 | B8: Aiguafreda | C8: 1013 | D8: 285 | E8: 1298 | F8: 0 | G8: 1298 | H8: 3
A9: 430017 | B9: Aiguamúrcia | C9: 404 | D9: 472 | E9: 876 | F9: 0 | G9: 876 | H9: 0
A10: 170025 | B10: Aiguaviva | C10: 243 | D10: 55 | E10: 298 | F10: 0 | G10: 298 | H10: 0
A11: 250387 | B11: Aitona | C11: 834 | D11: 384 | E11: 1218 | F11: 0 | G11: 1218 | H11: 2
A12: 250045 | B12: Alamús, els | C12: 293 | D12: 179 | E12: 472 | F12: 0 | G12: 472 | H12: 1
... A948: 430521 | B948: Xerta | C948: 486 | D948: 369 | E948: 855 | F948: 0 | G948: 855 | H948: 0

Sheet prepared_codes
A1: raw_municipality | B1: municipality_code | C1: municipality_name | D1: county_code | E1: county_name | F1: import_notes
A2: [250019] Abella de la Conca | B2: 250019 | C2: Abella de la Conca | D2: 25 | E2: Pallars Jussà
A3: [080018] Abrera | B3: 080018 | C3: Abrera | D3: 11 | E3: Baix Llobregat
A4: [250024] Àger | B4: 250024 | C4: Àger | D4: 23 | E4: Noguera
A5: [250030] Agramunt | B5: 250030 | C5: Agramunt | D5: 38 | E5: Urgell
A6: [080023] Aguilar de Segarra | B6: 080023 | C6: Aguilar de Segarra | D6: 07 | E6: Bages
A7: [170010] Agullana | B7: 170010 | C7: Agullana | D7: 02 | E7: Alt Empordà
A8: [080142] Aiguafreda | B8: 080142 | C8: Aiguafreda | D8: 24 | E8: Osona
A9: [430017] Aiguamúrcia | B9: 430017 | C9: Aiguamúrcia | D9: 01 | E9: Alt Camp
A10: [170025] Aiguaviva | B10: 170025 | C10: Aiguaviva | D10: 20 | E10: Gironès
A11: [250387] Aitona | B11: 250387 | C11: Aitona | D11: 33 | E11: Segrià
A12: [250045] Alamús, els | B12: 250045 | C12: Alamús, els | D12: 33 | E12: Segrià
A13: [250058] Alàs i Cerc | B13: 250058 | C13: Alàs i Cerc | D13: 04 | E13: Alt Urgell
... A948: [430521] Xerta | B948: 430521 | C948: Xerta | D948: 09 | E948: Baix Ebre

Sheet prepared_surface
A1: raw_municipality | B1: municipality_code | C1: municipality_name | D1: surface_km2 | E1: value_status | F1: import_notes
A2: [250019] Abella de la Conca | B2: 250019 | C2: Abella de la Conca | D2: 78.27 | F2: Publicació municipal 2025; la superfície s'utilitza com a magnitud territorial
A3: [080018] Abrera | B3: 080018 | C3: Abrera | D3: 19.94 | F3: Publicació municipal 2025; la superfície s'utilitza com a magnitud territorial
A4: [250024] Àger | B4: 250024 | C4: Àger | D4: 160.57 | F4: Publicació municipal 2025; la superfície s'utilitza com a magnitud territorial
A5: [250030] Agramunt | B5: 250030 | C5: Agramunt | D5: 79.65 | F5: Publicació municipal 2025; la superfície s'utilitza com a magnitud territorial
A6: [080023] Aguilar de Segarra | B6: 080023 | C6: Aguilar de Segarra | D6: 43.32 | F6: Publicació municipal 2025; la superfície s'utilitza com a magnitud territorial
A7: [170010] Agullana | B7: 170010 | C7: Agullana | D7: 27.73 | F7: Publicació municipal 2025; la superfície s'utilitza com a magnitud territorial
A8: [080142] Aiguafreda | B8: 080142 | C8: Aiguafreda | D8: 7.9 | F8: Publicació municipal 2025; la superfície s'utilitza com a magnitud territorial
A9: [430017] Aiguamúrcia | B9: 430017 | C9: Aiguamúrcia | D9: 72.95 | F9: Publicació municipal 2025; la superfície s'utilitza com a magnitud territorial
A10: [170025] Aiguaviva | B10: 170025 | C10: Aiguaviva | D10: 13.91 | F10: Publicació municipal 2025; la superfície s'utilitza com a magnitud territorial
A11: [250387] Aitona | B11: 250387 | C11: Aitona | D11: 66.9 | F11: Publicació municipal 2025; la superfície s'utilitza com a magnitud territorial
A12: [250045] Alamús, els | B12: 250045 | C12: Alamús, els | D12: 20.53 | F12: Publicació municipal 2025; la superfície s'utilitza com a magnitud territorial
A13: [250058] Alàs i Cerc | B13: 250058 | C13: Alàs i Cerc | D13: 57.67 | F13: Publicació municipal 2025; la superfície s'utilitza com a magnitud territorial
... A948: [430521] Xerta | B948: 430521 | C948: Xerta | D948: 32.39 | F948: Publicació municipal 2025; la superfície s'utilitza com a magnitud territorial

Sheet prepared_population
A1: year | B1: municipality_code | C1: municipality_name | D1: age_code | E1: age_label | F1: age_years | G1: population_total_sex | H1: value_status | I1: import_notes
A2: 2021 | B2: 430120 | C2: Altafulla | D2: Y000 | E2: 0 anys | F2: 0 | G2: 40 | I2: Total de tots els sexes; resposta JSON-stat de l'API d'Idescat
A3: 2021 | B3: 430120 | C3: Altafulla | D3: Y001 | E3: 1 any | F3: 1 | G3: 50 | I3: Total de tots els sexes; resposta JSON-stat de l'API d'Idescat
A4: 2021 | B4: 430120 | C4: Altafulla | D4: Y002 | E4: 2 anys | F4: 2 | G4: 44 | I4: Total de tots els sexes; resposta JSON-stat de l'API d'Idescat
A5: 2021 | B5: 430120 | C5: Altafulla | D5: Y003 | E5: 3 anys | F5: 3 | G5: 58 | I5: Total de tots els sexes; resposta JSON-stat de l'API d'Idescat
A6: 2021 | B6: 430120 | C6: Altafulla | D6: Y004 | E6: 4 anys | F6: 4 | G6: 73 | I6: Total de tots els sexes; resposta JSON-stat de l'API d'Idescat
A7: 2021 | B7: 430120 | C7: Altafulla | D7: Y005 | E7: 5 anys | F7: 5 | G7: 55 | I7: Total de tots els sexes; resposta JSON-stat de l'API d'Idescat
A8: 2021 | B8: 430120 | C8: Altafulla | D8: Y006 | E8: 6 anys | F8: 6 | G8: 68 | I8: Total de tots els sexes; resposta JSON-stat de l'API d'Idescat
A9: 2021 | B9: 430120 | C9: Altafulla | D9: Y007 | E9: 7 anys | F9: 7 | G9: 69 | I9: Total de tots els sexes; resposta JSON-stat de l'API d'Idescat
A10: 2021 | B10: 430120 | C10: Altafulla | D10: Y008 | E10: 8 anys | F10: 8 | G10: 68 | I10: Total de tots els sexes; resposta JSON-stat de l'API d'Idescat
A11: 2021 | B11: 430120 | C11: Altafulla | D11: Y009 | E11: 9 anys | F11: 9 | G11: 60 | I11: Total de tots els sexes; resposta JSON-stat de l'API d'Idescat
A12: 2021 | B12: 430120 | C12: Altafulla | D12: Y010 | E12: 10 anys | F12: 10 | G12: 81 | I12: Total de tots els sexes; resposta JSON-stat de l'API d'Idescat
A13: 2021 | B13: 430120 | C13: Altafulla | D13: Y011 | E13: 11 anys | F13: 11 | G13: 70 | I13: Total de tots els sexes; resposta JSON-stat de l'API d'Idescat
... A102: 2021 | B102: 430120 | C102: Altafulla | D102: Y_GE100 | E102: 100 anys o més | F102: 100 | G102: 2 | I102: Total de tots els sexes; resposta JSON-stat de l'API d'Idescat
A103: 2021 | B103: 430120 | C103: Altafulla | D103: TOTAL | E103: total | G103: 5496 | I103: Total de tots els sexes; resposta JSON-stat de l'API d'Idescat
A104: 2021 | B104: 439076 | C104: Canonja, la | D104: Y000 | E104: 0 anys | F104: 0 | G104: 48 | I104: Total de tots els sexes; resposta JSON-stat de l'API d'Idescat
A105: 2021 | B105: 439076 | C105: Canonja, la | D105: Y001 | E105: 1 any | F105: 1 | G105: 55 | I105: Total de tots els sexes; resposta JSON-stat de l'API d'Idescat
A106: 2021 | B106: 439076 | C106: Canonja, la | D106: Y002 | E106: 2 anys | F106: 2 | G106: 56 | I106: Total de tots els sexes; resposta JSON-stat de l'API d'Idescat
A107: 2021 | B107: 439076 | C107: Canonja, la | D107: Y003 | E107: 3 anys | F107: 3 | G107: 53 | I107: Total de tots els sexes; resposta JSON-stat de l'API d'Idescat
A108: 2021 | B108: 439076 | C108: Canonja, la | D108: Y004 | E108: 4 anys | F108: 4 | G108: 67 | I108: Total de tots els sexes; resposta JSON-stat de l'API d'Idescat
A109: 2021 | B109: 439076 | C109: Canonja, la | D109: Y005 | E109: 5 anys | F109: 5 | G109: 55 | I109: Total de tots els sexes; resposta JSON-stat de l'API d'Idescat
A110: 2021 | B110: 439076 | C110: Canonja, la | D110: Y006 | E110: 6 anys | F110: 6 | G110: 65 | I110: Total de tots els sexes; resposta JSON-stat de l'API d'Idescat
A111: 2021 | B111: 439076 | C111: Canonja, la | D111: Y007 | E111: 7 anys | F111: 7 | G111: 64 | I111: Total de tots els sexes; resposta JSON-stat de l'API d'Idescat
A112: 2021 | B112: 439076 | C112: Canonja, la | D112: Y008 | E112: 8 anys | F112: 8 | G112: 64 | I112: Total de tots els sexes; resposta JSON-stat de l'API d'Idescat
A113: 2021 | B113: 439076 | C113: Canonja, la | D113: Y009 | E113: 9 anys | F113: 9 | G113: 76 | I113: Total de tots els sexes; resposta JSON-stat de l'API d'Idescat
A114: 2021 | B114: 439076 | C114: Canonja, la | D114: Y010 | E114: 10 anys | F114: 10 | G114: 81 | I114: Total de tots els sexes; resposta JSON-stat de l'API d'Idescat
A115: 2021 | B115: 439076 | C115: Canonja, la | D115: Y011 | E115: 11 anys | F115: 11 | G115: 86 | I115: Total de tots els sexes; resposta JSON-stat de l'API d'Idescat
... A204: 2021 | B204: 439076 | C204: Canonja, la | D204: Y_GE100 | E204: 100 anys o més | F204: 100 | G204: 1 | I204: Total de tots els sexes; resposta JSON-stat de l'API d'Idescat
A205: 2021 | B205: 439076 | C205: Canonja, la | D205: TOTAL | E205: total | G205: 5971 | I205: Total de tots els sexes; resposta JSON-stat de l'API d'Idescat
A206: 2021 | B206: 430430 | C206: Catllar, el | D206: Y000 | E206: 0 anys | F206: 0 | G206: 38 | I206: Total de tots els sexes; resposta JSON-stat de l'API d'Idescat
A207: 2021 | B207: 430430 | C207: Catllar, el | D207: Y001 | E207: 1 any | F207: 1 | G207: 42 | I207: Total de tots els sexes; resposta JSON-stat de l'API d'Idescat
A208: 2021 | B208: 430430 | C208: Catllar, el | D208: Y002 | E208: 2 anys | F208: 2 | G208: 43 | I208: Total de tots els sexes; resposta JSON-stat de l'API d'Idescat
A209: 2021 | B209: 430430 | C209: Catllar, el | D209: Y003 | E209: 3 anys | F209: 3 | G209: 41 | I209: Total de tots els sexes; resposta JSON-stat de l'API d'Idescat
A210: 2021 | B210: 430430 | C210: Catllar, el | D210: Y004 | E210: 4 anys | F210: 4 | G210: 50 | I210: Total de tots els sexes; resposta JSON-stat de l'API d'Idescat
A211: 2021 | B211: 430430 | C211: Catllar, el | D211: Y005 | E211: 5 anys | F211: 5 | G211: 57 | I211: Total de tots els sexes; resposta JSON-stat de l'API d'Idescat
A212: 2021 | B212: 430430 | C212: Catllar, el | D212: Y006 | E212: 6 anys | F212: 6 | G212: 53 | I212: Total de tots els sexes; resposta JSON-stat de l'API d'Idescat
A213: 2021 | B213: 430430 | C213: Catllar, el | D213: Y007 | E213: 7 anys | F213: 7 | G213: 62 | I213: Total de tots els sexes; resposta JSON-stat de l'API d'Idescat
A214: 2021 | B214: 430430 | C214: Catllar, el | D214: Y008 | E214: 8 anys | F214: 8 | G214: 55 | I214: Total de tots els sexes; resposta JSON-stat de l'API d'Idescat
A215: 2021 | B215: 430430 | C215: Catllar, el | D215: Y009 | E215: 9 anys | F215: 9 | G215: 53 | I215: Total de tots els sexes; resposta JSON-stat de l'API d'Idescat
A216: 2021 | B216: 430430 | C216: Catllar, el | D216: Y010 | E216: 10 anys | F216: 10 | G216: 46 | I216: Total de tots els sexes; resposta JSON-stat de l'API d'Idescat
...

Sheet prepared_housing
A1: raw_municipality | B1: municipality_code | C1: municipality_name | D1: housing_total | E1: housing_main | F1: housing_non_main | G1: value_status | H1: import_notes
A2: [250019] Abella de la Conca | B2: 250019 | C2: Abella de la Conca | D2: 117 | E2: 65 | F2: 52 | H2: Total habitatges familiars; principal i no principal provenen de les categories publicades
A3: [080018] Abrera | B3: 080018 | C3: Abrera | D3: 5266 | E3: 4643 | F3: 623 | H3: Total habitatges familiars; principal i no principal provenen de les categories publicades
A4: [250024] Àger | B4: 250024 | C4: Àger | D4: 692 | E4: 239 | F4: 453 | H4: Total habitatges familiars; principal i no principal provenen de les categories publicades
A5: [250030] Agramunt | B5: 250030 | C5: Agramunt | D5: 2745 | E5: 2049 | F5: 696 | H5: Total habitatges familiars; principal i no principal provenen de les categories publicades
A6: [080023] Aguilar de Segarra | B6: 080023 | C6: Aguilar de Segarra | D6: 151 | E6: 99 | F6: 52 | H6: Total habitatges familiars; principal i no principal provenen de les categories publicades
A7: [170010] Agullana | B7: 170010 | C7: Agullana | D7: 589 | E7: 350 | F7: 239 | H7: Total habitatges familiars; principal i no principal provenen de les categories publicades
A8: [080142] Aiguafreda | B8: 080142 | C8: Aiguafreda | D8: 1298 | E8: 1013 | F8: 285 | H8: Total habitatges familiars; principal i no principal provenen de les categories publicades
A9: [430017] Aiguamúrcia | B9: 430017 | C9: Aiguamúrcia | D9: 876 | E9: 404 | F9: 472 | H9: Total habitatges familiars; principal i no principal provenen de les categories publicades
A10: [170025] Aiguaviva | B10: 170025 | C10: Aiguaviva | D10: 298 | E10: 243 | F10: 55 | H10: Total habitatges familiars; principal i no principal provenen de les categories publicades
A11: [250387] Aitona | B11: 250387 | C11: Aitona | D11: 1218 | E11: 834 | F11: 384 | H11: Total habitatges familiars; principal i no principal provenen de les categories publicades
A12: [250045] Alamús, els | B12: 250045 | C12: Alamús, els | D12: 472 | E12: 293 | F12: 179 | H12: Total habitatges familiars; principal i no principal provenen de les categories publicades
A13: [250058] Alàs i Cerc | B13: 250058 | C13: Alàs i Cerc | D13: 305 | E13: 142 | F13: 163 | H13: Total habitatges familiars; principal i no principal provenen de les categories publicades
... A948: [430521] Xerta | B948: 430521 | C948: Xerta | D948: 855 | E948: 486 | F948: 369 | H948: Total habitatges familiars; principal i no principal provenen de les categories publicades

Sheet checks
A1: check_id | B1: scope | C1: test | D1: expected | E1: observed | F1: status | G1: notes
A2: C01 | B2: source_codes | C2: Files municipals importades | D2: 947 | E2: 947 | F2: OK | G2: Capçalera detectada: Codi, Nom, Codi comarca, Nom comarca
A3: C02 | B3: prepared_codes | C3: Codis municipals duplicats | D3: 0 | E3: 0 | F3: OK | G3: Clau de sis caràcters conservada com a text
A4: C03 | B4: municipal | C4: Municipis del Tarragonès | D4: 22 | E4: 22 | F4: OK | G4: Filtrats amb el codi de comarca 36
A5: C04 | B5: municipal | C5: Fonts sense correspondència | D5: 0 | E5: 0 | F5: OK | G5: Població, habitatge i superfície contrastats per codi
A6: C05 | B6: municipal | C6: Suma dels grups d'edat diferent del total | D6: 0 o documentat | E6: 0 | F6: OK | G6: No es força la coincidència si la font presenta arrodoniments
A7: C06 | B7: municipal | C7: Municipi de control | D7: 431711 Vila-seca | E7: 431711 Vila-seca | F7: OK | G7: Codi contrastat entre les quatre fonts
A8: C07 | B8: source_surface | C8: Període de la superfície | D8: Compatibilitat documentada | E8: Publicació 2025 | F8: REVISAR | G8: Cal justificar l'ús com a denominador de població 2021 o obtenir una edició territorial equivalent
A9: C08 | B9: indicators_* | C9: Files municipals i codis únics | D9: 22 i 22 | E9: 22 i 22 | F9: OK | G9: Una fila per municipi a cada família
A10: C09 | B10: indicators_* | C10: Denominadors no positius | D10: 0 | E10: 0 | F10: OK | G10: Població, població jove, superfície, habitatges totals i principals
A11: C10 | B11: municipal | C11: Components diferents dels totals | D11: 0 | E11: 0 | F11: OK | G11: Població i habitatges reconstruïts
A12: C11 | B12: indicators_* | C12: Fórmules municipals | D12: 132 | E12: 132 | F12: OK | G12: Sis indicadors per 22 municipis
A13: C12 | B13: indicators_* | C13: Percentatges fora de 0–100 | D13: 0 | E13: 0 | F13: OK | G13: Pes jove, pes gran i habitatge no principal
A14: C13 | B14: indicators_summary | C14: Agregats calculats des de components | D14: 8 | E14: 8 | F14: OK | G14: No s'utilitzen mitjanes simples de percentatges
A15: C14 | B15: indicators_summary | C15: Superfície temporalment compatible | D15: Justificació | E15: Pendent | F15: REVISAR | G15: La densitat continua provisional fins a resoldre C07

Sheet municipal
A1: municipality_code | B1: municipality_name | C1: county_code | D1: county_name | E1: population_total | F1: population_0_14 | G1: population_15_64 | H1: population_65_plus | I1: housing_total | J1: housing_main | K1: housing_non_main | L1: surface_km2 | M1: preparation_notes
A2: =prepared_codes!B48 | B2: =prepared_codes!C48 | C2: =prepared_codes!D48 | D2: =prepared_codes!E48 | E2: =SUMIFS(prepared_population!$G:$G,prepared_population!$B:$B,$A2,prepared_population!$D:$D,"TOTAL") | F2: =SUMIFS(prepared_population!$G:$G,prepared_population!$B:$B,$A2,prepared_population!$F:$F,">=0",prepared_population!$F:$F,"<=14") | G2: =SUMIFS(prepared_population!$G:$G,prepared_population!$B:$B,$A2,prepared_population!$F:$F,">=15",prepared_population!$F:$F,"<=64") | H2: =SUMIFS(prepared_population!$G:$G,prepared_population!$B:$B,$A2,prepared_population!$F:$F,">=65") | I2: =prepared_housing!D48 | J2: =prepared_housing!E48 | K2: =prepared_housing!F48 | L2: =prepared_surface!D48 | M2: Població i habitatge: 2021; superfície: publicació 2025, amb compatibilitat territorial pendent de revisió explícita
A3: =prepared_codes!B222 | B3: =prepared_codes!C222 | C3: =prepared_codes!D222 | D3: =prepared_codes!E222 | E3: =SUMIFS(prepared_population!$G:$G,prepared_population!$B:$B,$A3,prepared_population!$D:$D,"TOTAL") | F3: =SUMIFS(prepared_population!$G:$G,prepared_population!$B:$B,$A3,prepared_population!$F:$F,">=0",prepared_population!$F:$F,"<=14") | G3: =SUMIFS(prepared_population!$G:$G,prepared_population!$B:$B,$A3,prepared_population!$F:$F,">=15",prepared_population!$F:$F,"<=64") | H3: =SUMIFS(prepared_population!$G:$G,prepared_population!$B:$B,$A3,prepared_population!$F:$F,">=65") | I3: =prepared_housing!D222 | J3: =prepared_housing!E222 | K3: =prepared_housing!F222 | L3: =prepared_surface!D222 | M3: Població i habitatge: 2021; superfície: publicació 2025, amb compatibilitat territorial pendent de revisió explícita
A4: =prepared_codes!B246 | B4: =prepared_codes!C246 | C4: =prepared_codes!D246 | D4: =prepared_codes!E246 | E4: =SUMIFS(prepared_population!$G:$G,prepared_population!$B:$B,$A4,prepared_population!$D:$D,"TOTAL") | F4: =SUMIFS(prepared_population!$G:$G,prepared_population!$B:$B,$A4,prepared_population!$F:$F,">=0",prepared_population!$F:$F,"<=14") | G4: =SUMIFS(prepared_population!$G:$G,prepared_population!$B:$B,$A4,prepared_population!$F:$F,">=15",prepared_population!$F:$F,"<=64") | H4: =SUMIFS(prepared_population!$G:$G,prepared_population!$B:$B,$A4,prepared_population!$F:$F,">=65") | I4: =prepared_housing!D246 | J4: =prepared_housing!E246 | K4: =prepared_housing!F246 | L4: =prepared_surface!D246 | M4: Població i habitatge: 2021; superfície: publicació 2025, amb compatibilitat territorial pendent de revisió explícita
A5: =prepared_codes!B255 | B5: =prepared_codes!C255 | C5: =prepared_codes!D255 | D5: =prepared_codes!E255 | E5: =SUMIFS(prepared_population!$G:$G,prepared_population!$B:$B,$A5,prepared_population!$D:$D,"TOTAL") | F5: =SUMIFS(prepared_population!$G:$G,prepared_population!$B:$B,$A5,prepared_population!$F:$F,">=0",prepared_population!$F:$F,"<=14") | G5: =SUMIFS(prepared_population!$G:$G,prepared_population!$B:$B,$A5,prepared_population!$F:$F,">=15",prepared_population!$F:$F,"<=64") | H5: =SUMIFS(prepared_population!$G:$G,prepared_population!$B:$B,$A5,prepared_population!$F:$F,">=65") | I5: =prepared_housing!D255 | J5: =prepared_housing!E255 | K5: =prepared_housing!F255 | L5: =prepared_surface!D255 | M5: Població i habitatge: 2021; superfície: publicació 2025, amb compatibilitat territorial pendent de revisió explícita
A6: =prepared_codes!B475 | B6: =prepared_codes!C475 | C6: =prepared_codes!D475 | D6: =prepared_codes!E475 | E6: =SUMIFS(prepared_population!$G:$G,prepared_population!$B:$B,$A6,prepared_population!$D:$D,"TOTAL") | F6: =SUMIFS(prepared_population!$G:$G,prepared_population!$B:$B,$A6,prepared_population!$F:$F,">=0",prepared_population!$F:$F,"<=14") | G6: =SUMIFS(prepared_population!$G:$G,prepared_population!$B:$B,$A6,prepared_population!$F:$F,">=15",prepared_population!$F:$F,"<=64") | H6: =SUMIFS(prepared_population!$G:$G,prepared_population!$B:$B,$A6,prepared_population!$F:$F,">=65") | I6: =prepared_housing!D475 | J6: =prepared_housing!E475 | K6: =prepared_housing!F475 | L6: =prepared_surface!D475 | M6: Població i habitatge: 2021; superfície: publicació 2025, amb compatibilitat territorial pendent de revisió explícita
A7: =prepared_codes!B486 | B7: =prepared_codes!C486 | C7: =prepared_codes!D486 | D7: =prepared_codes!E486 | E7: =SUMIFS(prepared_population!$G:$G,prepared_population!$B:$B,$A7,prepared_population!$D:$D,"TOTAL") | F7: =SUMIFS(prepared_population!$G:$G,prepared_population!$B:$B,$A7,prepared_population!$F:$F,">=0",prepared_population!$F:$F,"<=14") | G7: =SUMIFS(prepared_population!$G:$G,prepared_population!$B:$B,$A7,prepared_population!$F:$F,">=15",prepared_population!$F:$F,"<=64") | H7: =SUMIFS(prepared_population!$G:$G,prepared_population!$B:$B,$A7,prepared_population!$F:$F,">=65") | I7: =prepared_housing!D486 | J7: =prepared_housing!E486 | K7: =prepared_housing!F486 | L7: =prepared_surface!D486 | M7: Població i habitatge: 2021; superfície: publicació 2025, amb compatibilitat territorial pendent de revisió explícita
A8: =prepared_codes!B522 | B8: =prepared_codes!C522 | C8: =prepared_codes!D522 | D8: =prepared_codes!E522 | E8: =SUMIFS(prepared_population!$G:$G,prepared_population!$B:$B,$A8,prepared_population!$D:$D,"TOTAL") | F8: =SUMIFS(prepared_population!$G:$G,prepared_population!$B:$B,$A8,prepared_population!$F:$F,">=0",prepared_population!$F:$F,"<=14") | G8: =SUMIFS(prepared_population!$G:$G,prepared_population!$B:$B,$A8,prepared_population!$F:$F,">=15",prepared_population!$F:$F,"<=64") | H8: =SUMIFS(prepared_population!$G:$G,prepared_population!$B:$B,$A8,prepared_population!$F:$F,">=65") | I8: =prepared_housing!D522 | J8: =prepared_housing!E522 | K8: =prepared_housing!F522 | L8: =prepared_surface!D522 | M8: Població i habitatge: 2021; superfície: publicació 2025, amb compatibilitat territorial pendent de revisió explícita
A9: =prepared_codes!B539 | B9: =prepared_codes!C539 | C9: =prepared_codes!D539 | D9: =prepared_codes!E539 | E9: =SUMIFS(prepared_population!$G:$G,prepared_population!$B:$B,$A9,prepared_population!$D:$D,"TOTAL") | F9: =SUMIFS(prepared_population!$G:$G,prepared_population!$B:$B,$A9,prepared_population!$F:$F,">=0",prepared_population!$F:$F,"<=14") | G9: =SUMIFS(prepared_population!$G:$G,prepared_population!$B:$B,$A9,prepared_population!$F:$F,">=15",prepared_population!$F:$F,"<=64") | H9: =SUMIFS(prepared_population!$G:$G,prepared_population!$B:$B,$A9,prepared_population!$F:$F,">=65") | I9: =prepared_housing!D539 | J9: =prepared_housing!E539 | K9: =prepared_housing!F539 | L9: =prepared_surface!D539 | M9: Població i habitatge: 2021; superfície: publicació 2025, amb compatibilitat territorial pendent de revisió explícita
A10: =prepared_codes!B559 | B10: =prepared_codes!C559 | C10: =prepared_codes!D559 | D10: =prepared_codes!E559 | E10: =SUMIFS(prepared_population!$G:$G,prepared_population!$B:$B,$A10,prepared_population!$D:$D,"TOTAL") | F10: =SUMIFS(prepared_population!$G:$G,prepared_population!$B:$B,$A10,prepared_population!$F:$F,">=0",prepared_population!$F:$F,"<=14") | G10: =SUMIFS(prepared_population!$G:$G,prepared_population!$B:$B,$A10,prepared_population!$F:$F,">=15",prepared_population!$F:$F,"<=64") | H10: =SUMIFS(prepared_population!$G:$G,prepared_population!$B:$B,$A10,prepared_population!$F:$F,">=65") | I10: =prepared_housing!D559 | J10: =prepared_housing!E559 | K10: =prepared_housing!F559 | L10: =prepared_surface!D559 | M10: Població i habitatge: 2021; superfície: publicació 2025, amb compatibilitat territorial pendent de revisió explícita
A11: =prepared_codes!B561 | B11: =prepared_codes!C561 | C11: =prepared_codes!D561 | D11: =prepared_codes!E561 | E11: =SUMIFS(prepared_population!$G:$G,prepared_population!$B:$B,$A11,prepared_population!$D:$D,"TOTAL") | F11: =SUMIFS(prepared_population!$G:$G,prepared_population!$B:$B,$A11,prepared_population!$F:$F,">=0",prepared_population!$F:$F,"<=14") | G11: =SUMIFS(prepared_population!$G:$G,prepared_population!$B:$B,$A11,prepared_population!$F:$F,">=15",prepared_population!$F:$F,"<=64") | H11: =SUMIFS(prepared_population!$G:$G,prepared_population!$B:$B,$A11,prepared_population!$F:$F,">=65") | I11: =prepared_housing!D561 | J11: =prepared_housing!E561 | K11: =prepared_housing!F561 | L11: =prepared_surface!D561 | M11: Població i habitatge: 2021; superfície: publicació 2025, amb compatibilitat territorial pendent de revisió explícita
A12: =prepared_codes!B611 | B12: =prepared_codes!C611 | C12: =prepared_codes!D611 | D12: =prepared_codes!E611 | E12: =SUMIFS(prepared_population!$G:$G,prepared_population!$B:$B,$A12,prepared_population!$D:$D,"TOTAL") | F12: =SUMIFS(prepared_population!$G:$G,prepared_population!$B:$B,$A12,prepared_population!$F:$F,">=0",prepared_population!$F:$F,"<=14") | G12: =SUMIFS(prepared_population!$G:$G,prepared_population!$B:$B,$A12,prepared_population!$F:$F,">=15",prepared_population!$F:$F,"<=64") | H12: =SUMIFS(prepared_population!$G:$G,prepared_population!$B:$B,$A12,prepared_population!$F:$F,">=65") | I12: =prepared_housing!D611 | J12: =prepared_housing!E611 | K12: =prepared_housing!F611 | L12: =prepared_surface!D611 | M12: Població i habitatge: 2021; superfície: publicació 2025, amb compatibilitat territorial pendent de revisió explícita
A13: =prepared_codes!B620 | B13: =prepared_codes!C620 | C13: =prepared_codes!D620 | D13: =prepared_codes!E620 | E13: =SUMIFS(prepared_population!$G:$G,prepared_population!$B:$B,$A13,prepared_population!$D:$D,"TOTAL") | F13: =SUMIFS(prepared_population!$G:$G,prepared_population!$B:$B,$A13,prepared_population!$F:$F,">=0",prepared_population!$F:$F,"<=14") | G13: =SUMIFS(prepared_population!$G:$G,prepared_population!$B:$B,$A13,prepared_population!$F:$F,">=15",prepared_population!$F:$F,"<=64") | H13: =SUMIFS(prepared_population!$G:$G,prepared_population!$B:$B,$A13,prepared_population!$F:$F,">=65") | I13: =prepared_housing!D620 | J13: =prepared_housing!E620 | K13: =prepared_housing!F620 | L13: =prepared_surface!D620 | M13: Població i habitatge: 2021; superfície: publicació 2025, amb compatibilitat territorial pendent de revisió explícita
A14: =prepared_codes!B634 | B14: =prepared_codes!C634 | C14: =prepared_codes!D634 | D14: =prepared_codes!E634 | E14: =SUMIFS(prepared_population!$G:$G,prepared_population!$B:$B,$A14,prepared_population!$D:$D,"TOTAL") | F14: =SUMIFS(prepared_population!$G:$G,prepared_population!$B:$B,$A14,prepared_population!$F:$F,">=0",prepared_population!$F:$F,"<=14") | G14: =SUMIFS(prepared_population!$G:$G,prepared_population!$B:$B,$A14,prepared_population!$F:$F,">=15",prepared_population!$F:$F,"<=64") | H14: =SUMIFS(prepared_population!$G:$G,prepared_population!$B:$B,$A14,prepared_population!$F:$F,">=65") | I14: =prepared_housing!D634 | J14: =prepared_housing!E634 | K14: =prepared_housing!F634 | L14: =prepared_surface!D634 | M14: Població i habitatge: 2021; superfície: publicació 2025, amb compatibilitat territorial pendent de revisió explícita
A15: =prepared_codes!B651 | B15: =prepared_codes!C651 | C15: =prepared_codes!D651 | D15: =prepared_codes!E651 | E15: =SUMIFS(prepared_population!$G:$G,prepared_population!$B:$B,$A15,prepared_population!$D:$D,"TOTAL") | F15: =SUMIFS(prepared_population!$G:$G,prepared_population!$B:$B,$A15,prepared_population!$F:$F,">=0",prepared_population!$F:$F,"<=14") | G15: =SUMIFS(prepared_population!$G:$G,prepared_population!$B:$B,$A15,prepared_population!$F:$F,">=15",prepared_population!$F:$F,"<=64") | H15: =SUMIFS(prepared_population!$G:$G,prepared_population!$B:$B,$A15,prepared_population!$F:$F,">=65") | I15: =prepared_housing!D651 | J15: =prepared_housing!E651 | K15: =prepared_housing!F651 | L15: =prepared_surface!D651 | M15: Població i habitatge: 2021; superfície: publicació 2025, amb compatibilitat territorial pendent de revisió explícita
A16: =prepared_codes!B771 | B16: =prepared_codes!C771 | C16: =prepared_codes!D771 | D16: =prepared_codes!E771 | E16: =SUMIFS(prepared_population!$G:$G,prepared_population!$B:$B,$A16,prepared_population!$D:$D,"TOTAL") | F16: =SUMIFS(prepared_population!$G:$G,prepared_population!$B:$B,$A16,prepared_population!$F:$F,">=0",prepared_population!$F:$F,"<=14") | G16: =SUMIFS(prepared_population!$G:$G,prepared_population!$B:$B,$A16,prepared_population!$F:$F,">=15",prepared_population!$F:$F,"<=64") | H16: =SUMIFS(prepared_population!$G:$G,prepared_population!$B:$B,$A16,prepared_population!$F:$F,">=65") | I16: =prepared_housing!D771 | J16: =prepared_housing!E771 | K16: =prepared_housing!F771 | L16: =prepared_surface!D771 | M16: Població i habitatge: 2021; superfície: publicació 2025, amb compatibilitat territorial pendent de revisió explícita
A17: =prepared_codes!B808 | B17: =prepared_codes!C808 | C17: =prepared_codes!D808 | D17: =prepared_codes!E808 | E17: =SUMIFS(prepared_population!$G:$G,prepared_population!$B:$B,$A17,prepared_population!$D:$D,"TOTAL") | F17: =SUMIFS(prepared_population!$G:$G,prepared_population!$B:$B,$A17,prepared_population!$F:$F,">=0",prepared_population!$F:$F,"<=14") | G17: =SUMIFS(prepared_population!$G:$G,prepared_population!$B:$B,$A17,prepared_population!$F:$F,">=15",prepared_population!$F:$F,"<=64") | H17: =SUMIFS(prepared_population!$G:$G,prepared_population!$B:$B,$A17,prepared_population!$F:$F,">=65") | I17: =prepared_housing!D808 | J17: =prepared_housing!E808 | K17: =prepared_housing!F808 | L17: =prepared_surface!D808 | M17: Població i habitatge: 2021; superfície: publicació 2025, amb compatibilitat territorial pendent de revisió explícita
A18: =prepared_codes!B835 | B18: =prepared_codes!C835 | C18: =prepared_codes!D835 | D18: =prepared_codes!E835 | E18: =SUMIFS(prepared_population!$G:$G,prepared_population!$B:$B,$A18,prepared_population!$D:$D,"TOTAL") | F18: =SUMIFS(prepared_population!$G:$G,prepared_population!$B:$B,$A18,prepared_population!$F:$F,">=0",prepared_population!$F:$F,"<=14") | G18: =SUMIFS(prepared_population!$G:$G,prepared_population!$B:$B,$A18,prepared_population!$F:$F,">=15",prepared_population!$F:$F,"<=64") | H18: =SUMIFS(prepared_population!$G:$G,prepared_population!$B:$B,$A18,prepared_population!$F:$F,">=65") | I18: =prepared_housing!D834 | J18: =prepared_housing!E834 | K18: =prepared_housing!F834 | L18: =prepared_surface!D834 | M18: Població i habitatge: 2021; superfície: publicació 2025, amb compatibilitat territorial pendent de revisió explícita
A19: =prepared_codes!B888 | B19: =prepared_codes!C888 | C19: =prepared_codes!D888 | D19: =prepared_codes!E888 | E19: =SUMIFS(prepared_population!$G:$G,prepared_population!$B:$B,$A19,prepared_population!$D:$D,"TOTAL") | F19: =SUMIFS(prepared_population!$G:$G,prepared_population!$B:$B,$A19,prepared_population!$F:$F,">=0",prepared_population!$F:$F,"<=14") | G19: =SUMIFS(prepared_population!$G:$G,prepared_population!$B:$B,$A19,prepared_population!$F:$F,">=15",prepared_population!$F:$F,"<=64") | H19: =SUMIFS(prepared_population!$G:$G,prepared_population!$B:$B,$A19,prepared_population!$F:$F,">=65") | I19: =prepared_housing!D888 | J19: =prepared_housing!E888 | K19: =prepared_housing!F888 | L19: =prepared_surface!D888 | M19: Població i habitatge: 2021; superfície: publicació 2025, amb compatibilitat territorial pendent de revisió explícita
A20: =prepared_codes!B915 | B20: =prepared_codes!C915 | C20: =prepared_codes!D915 | D20: =prepared_codes!E915 | E20: =SUMIFS(prepared_population!$G:$G,prepared_population!$B:$B,$A20,prepared_population!$D:$D,"TOTAL") | F20: =SUMIFS(prepared_population!$G:$G,prepared_population!$B:$B,$A20,prepared_population!$F:$F,">=0",prepared_population!$F:$F,"<=14") | G20: =SUMIFS(prepared_population!$G:$G,prepared_population!$B:$B,$A20,prepared_population!$F:$F,">=15",prepared_population!$F:$F,"<=64") | H20: =SUMIFS(prepared_population!$G:$G,prepared_population!$B:$B,$A20,prepared_population!$F:$F,">=65") | I20: =prepared_housing!D911 | J20: =prepared_housing!E911 | K20: =prepared_housing!F911 | L20: =prepared_surface!D911 | M20: Població i habitatge: 2021; superfície: publicació 2025, amb compatibilitat territorial pendent de revisió explícita
A21: =prepared_codes!B896 | B21: =prepared_codes!C896 | C21: =prepared_codes!D896 | D21: =prepared_codes!E896 | E21: =SUMIFS(prepared_population!$G:$G,prepared_population!$B:$B,$A21,prepared_population!$D:$D,"TOTAL") | F21: =SUMIFS(prepared_population!$G:$G,prepared_population!$B:$B,$A21,prepared_population!$F:$F,">=0",prepared_population!$F:$F,"<=14") | G21: =SUMIFS(prepared_population!$G:$G,prepared_population!$B:$B,$A21,prepared_population!$F:$F,">=15",prepared_population!$F:$F,"<=64") | H21: =SUMIFS(prepared_population!$G:$G,prepared_population!$B:$B,$A21,prepared_population!$F:$F,">=65") | I21: =prepared_housing!D932 | J21: =prepared_housing!E932 | K21: =prepared_housing!F932 | L21: =prepared_surface!D932 | M21: Població i habitatge: 2021; superfície: publicació 2025, amb compatibilitat territorial pendent de revisió explícita
A22: =prepared_codes!B652 | B22: =prepared_codes!C652 | C22: =prepared_codes!D652 | D22: =prepared_codes!E652 | E22: =SUMIFS(prepared_population!$G:$G,prepared_population!$B:$B,$A22,prepared_population!$D:$D,"TOTAL") | F22: =SUMIFS(prepared_population!$G:$G,prepared_population!$B:$B,$A22,prepared_population!$F:$F,">=0",prepared_population!$F:$F,"<=14") | G22: =SUMIFS(prepared_population!$G:$G,prepared_population!$B:$B,$A22,prepared_population!$F:$F,">=15",prepared_population!$F:$F,"<=64") | H22: =SUMIFS(prepared_population!$G:$G,prepared_population!$B:$B,$A22,prepared_population!$F:$F,">=65") | I22: =prepared_housing!D652 | J22: =prepared_housing!E652 | K22: =prepared_housing!F652 | L22: =prepared_surface!D652 | M22: Població i habitatge: 2021; superfície: publicació 2025, amb compatibilitat territorial pendent de revisió explícita
A23: =prepared_codes!B179 | B23: =prepared_codes!C179 | C23: =prepared_codes!D179 | D23: =prepared_codes!E179 | E23: =SUMIFS(prepared_population!$G:$G,prepared_population!$B:$B,$A23,prepared_population!$D:$D,"TOTAL") | F23: =SUMIFS(prepared_population!$G:$G,prepared_population!$B:$B,$A23,prepared_population!$F:$F,">=0",prepared_population!$F:$F,"<=14") | G23: =SUMIFS(prepared_population!$G:$G,prepared_population!$B:$B,$A23,prepared_population!$F:$F,">=15",prepared_population!$F:$F,"<=64") | H23: =SUMIFS(prepared_population!$G:$G,prepared_population!$B:$B,$A23,prepared_population!$F:$F,">=65") | I23: =prepared_housing!D179 | J23: =prepared_housing!E179 | K23: =prepared_housing!F179 | L23: =prepared_surface!D179 | M23: Població i habitatge: 2021; superfície: publicació 2025, amb compatibilitat territorial pendent de revisió explícita

Sheet pivot_county_control
A1: Filtrar
A3: county_name | B3: Suma - municipality_code
A4: Alt Camp
A5: Alt Empordà
A6: Alt Penedès
A7: Alt Urgell
A8: Alta Ribagorça
A9: Anoia
A10: Aran
A11: Bages
A12: Baix Camp
A13: Baix Ebre
A14: Baix Empordà
A15: Baix Llobregat
... A47: Total Resultado

Sheet indicators_demography
A1: municipality_code | B1: municipality_name | C1: population_total | D1: population_0_14 | E1: population_65_plus | F1: surface_km2 | G1: population_0_14_pct | H1: population_65_plus_pct | I1: ageing_index_per_100_young | J1: population_density_hab_km2
A2: =municipal!A2 | B2: =municipal!B2 | C2: =municipal!E2 | D2: =municipal!F2 | E2: =municipal!H2 | F2: =municipal!L2 | G2: =IF(AND(ISNUMBER(D2),ISNUMBER(C2),C2>0),D2/C2*100,NA()) | H2: =IF(AND(ISNUMBER(E2),ISNUMBER(C2),C2>0),E2/C2*100,NA()) | I2: =IF(AND(ISNUMBER(E2),ISNUMBER(D2),D2>0),E2/D2*100,NA()) | J2: =IF(AND(ISNUMBER(C2),ISNUMBER(F2),F2>0),C2/F2,NA())
A3: =municipal!A3 | B3: =municipal!B3 | C3: =municipal!E3 | D3: =municipal!F3 | E3: =municipal!H3 | F3: =municipal!L3 | G3: =IF(AND(ISNUMBER(D3),ISNUMBER(C3),C3>0),D3/C3*100,NA()) | H3: =IF(AND(ISNUMBER(E3),ISNUMBER(C3),C3>0),E3/C3*100,NA()) | I3: =IF(AND(ISNUMBER(E3),ISNUMBER(D3),D3>0),E3/D3*100,NA()) | J3: =IF(AND(ISNUMBER(C3),ISNUMBER(F3),F3>0),C3/F3,NA())
A4: =municipal!A4 | B4: =municipal!B4 | C4: =municipal!E4 | D4: =municipal!F4 | E4: =municipal!H4 | F4: =municipal!L4 | G4: =IF(AND(ISNUMBER(D4),ISNUMBER(C4),C4>0),D4/C4*100,NA()) | H4: =IF(AND(ISNUMBER(E4),ISNUMBER(C4),C4>0),E4/C4*100,NA()) | I4: =IF(AND(ISNUMBER(E4),ISNUMBER(D4),D4>0),E4/D4*100,NA()) | J4: =IF(AND(ISNUMBER(C4),ISNUMBER(F4),F4>0),C4/F4,NA())
A5: =municipal!A5 | B5: =municipal!B5 | C5: =municipal!E5 | D5: =municipal!F5 | E5: =municipal!H5 | F5: =municipal!L5 | G5: =IF(AND(ISNUMBER(D5),ISNUMBER(C5),C5>0),D5/C5*100,NA()) | H5: =IF(AND(ISNUMBER(E5),ISNUMBER(C5),C5>0),E5/C5*100,NA()) | I5: =IF(AND(ISNUMBER(E5),ISNUMBER(D5),D5>0),E5/D5*100,NA()) | J5: =IF(AND(ISNUMBER(C5),ISNUMBER(F5),F5>0),C5/F5,NA())
A6: =municipal!A6 | B6: =municipal!B6 | C6: =municipal!E6 | D6: =municipal!F6 | E6: =municipal!H6 | F6: =municipal!L6 | G6: =IF(AND(ISNUMBER(D6),ISNUMBER(C6),C6>0),D6/C6*100,NA()) | H6: =IF(AND(ISNUMBER(E6),ISNUMBER(C6),C6>0),E6/C6*100,NA()) | I6: =IF(AND(ISNUMBER(E6),ISNUMBER(D6),D6>0),E6/D6*100,NA()) | J6: =IF(AND(ISNUMBER(C6),ISNUMBER(F6),F6>0),C6/F6,NA())
A7: =municipal!A7 | B7: =municipal!B7 | C7: =municipal!E7 | D7: =municipal!F7 | E7: =municipal!H7 | F7: =municipal!L7 | G7: =IF(AND(ISNUMBER(D7),ISNUMBER(C7),C7>0),D7/C7*100,NA()) | H7: =IF(AND(ISNUMBER(E7),ISNUMBER(C7),C7>0),E7/C7*100,NA()) | I7: =IF(AND(ISNUMBER(E7),ISNUMBER(D7),D7>0),E7/D7*100,NA()) | J7: =IF(AND(ISNUMBER(C7),ISNUMBER(F7),F7>0),C7/F7,NA())
A8: =municipal!A8 | B8: =municipal!B8 | C8: =municipal!E8 | D8: =municipal!F8 | E8: =municipal!H8 | F8: =municipal!L8 | G8: =IF(AND(ISNUMBER(D8),ISNUMBER(C8),C8>0),D8/C8*100,NA()) | H8: =IF(AND(ISNUMBER(E8),ISNUMBER(C8),C8>0),E8/C8*100,NA()) | I8: =IF(AND(ISNUMBER(E8),ISNUMBER(D8),D8>0),E8/D8*100,NA()) | J8: =IF(AND(ISNUMBER(C8),ISNUMBER(F8),F8>0),C8/F8,NA())
A9: =municipal!A9 | B9: =municipal!B9 | C9: =municipal!E9 | D9: =municipal!F9 | E9: =municipal!H9 | F9: =municipal!L9 | G9: =IF(AND(ISNUMBER(D9),ISNUMBER(C9),C9>0),D9/C9*100,NA()) | H9: =IF(AND(ISNUMBER(E9),ISNUMBER(C9),C9>0),E9/C9*100,NA()) | I9: =IF(AND(ISNUMBER(E9),ISNUMBER(D9),D9>0),E9/D9*100,NA()) | J9: =IF(AND(ISNUMBER(C9),ISNUMBER(F9),F9>0),C9/F9,NA())
A10: =municipal!A10 | B10: =municipal!B10 | C10: =municipal!E10 | D10: =municipal!F10 | E10: =municipal!H10 | F10: =municipal!L10 | G10: =IF(AND(ISNUMBER(D10),ISNUMBER(C10),C10>0),D10/C10*100,NA()) | H10: =IF(AND(ISNUMBER(E10),ISNUMBER(C10),C10>0),E10/C10*100,NA()) | I10: =IF(AND(ISNUMBER(E10),ISNUMBER(D10),D10>0),E10/D10*100,NA()) | J10: =IF(AND(ISNUMBER(C10),ISNUMBER(F10),F10>0),C10/F10,NA())
A11: =municipal!A11 | B11: =municipal!B11 | C11: =municipal!E11 | D11: =municipal!F11 | E11: =municipal!H11 | F11: =municipal!L11 | G11: =IF(AND(ISNUMBER(D11),ISNUMBER(C11),C11>0),D11/C11*100,NA()) | H11: =IF(AND(ISNUMBER(E11),ISNUMBER(C11),C11>0),E11/C11*100,NA()) | I11: =IF(AND(ISNUMBER(E11),ISNUMBER(D11),D11>0),E11/D11*100,NA()) | J11: =IF(AND(ISNUMBER(C11),ISNUMBER(F11),F11>0),C11/F11,NA())
A12: =municipal!A12 | B12: =municipal!B12 | C12: =municipal!E12 | D12: =municipal!F12 | E12: =municipal!H12 | F12: =municipal!L12 | G12: =IF(AND(ISNUMBER(D12),ISNUMBER(C12),C12>0),D12/C12*100,NA()) | H12: =IF(AND(ISNUMBER(E12),ISNUMBER(C12),C12>0),E12/C12*100,NA()) | I12: =IF(AND(ISNUMBER(E12),ISNUMBER(D12),D12>0),E12/D12*100,NA()) | J12: =IF(AND(ISNUMBER(C12),ISNUMBER(F12),F12>0),C12/F12,NA())
A13: =municipal!A13 | B13: =municipal!B13 | C13: =municipal!E13 | D13: =municipal!F13 | E13: =municipal!H13 | F13: =municipal!L13 | G13: =IF(AND(ISNUMBER(D13),ISNUMBER(C13),C13>0),D13/C13*100,NA()) | H13: =IF(AND(ISNUMBER(E13),ISNUMBER(C13),C13>0),E13/C13*100,NA()) | I13: =IF(AND(ISNUMBER(E13),ISNUMBER(D13),D13>0),E13/D13*100,NA()) | J13: =IF(AND(ISNUMBER(C13),ISNUMBER(F13),F13>0),C13/F13,NA())
... A23: =municipal!A23 | B23: =municipal!B23 | C23: =municipal!E23 | D23: =municipal!F23 | E23: =municipal!H23 | F23: =municipal!L23 | G23: =IF(AND(ISNUMBER(D23),ISNUMBER(C23),C23>0),D23/C23*100,NA()) | H23: =IF(AND(ISNUMBER(E23),ISNUMBER(C23),C23>0),E23/C23*100,NA()) | I23: =IF(AND(ISNUMBER(E23),ISNUMBER(D23),D23>0),E23/D23*100,NA()) | J23: =IF(AND(ISNUMBER(C23),ISNUMBER(F23),F23>0),C23/F23,NA())

Sheet indicators_housing
A1: municipality_code | B1: municipality_name | C1: population_total | D1: housing_total | E1: housing_main | F1: housing_non_main | G1: housing_non_main_pct | H1: residents_per_housing_main
A2: =municipal!A2 | B2: =municipal!B2 | C2: =municipal!E2 | D2: =municipal!I2 | E2: =municipal!J2 | F2: =municipal!K2 | G2: =IF(AND(ISNUMBER(F2),ISNUMBER(D2),D2>0),F2/D2*100,NA()) | H2: =IF(AND(ISNUMBER(C2),ISNUMBER(E2),E2>0),C2/E2,NA())
A3: =municipal!A3 | B3: =municipal!B3 | C3: =municipal!E3 | D3: =municipal!I3 | E3: =municipal!J3 | F3: =municipal!K3 | G3: =IF(AND(ISNUMBER(F3),ISNUMBER(D3),D3>0),F3/D3*100,NA()) | H3: =IF(AND(ISNUMBER(C3),ISNUMBER(E3),E3>0),C3/E3,NA())
A4: =municipal!A4 | B4: =municipal!B4 | C4: =municipal!E4 | D4: =municipal!I4 | E4: =municipal!J4 | F4: =municipal!K4 | G4: =IF(AND(ISNUMBER(F4),ISNUMBER(D4),D4>0),F4/D4*100,NA()) | H4: =IF(AND(ISNUMBER(C4),ISNUMBER(E4),E4>0),C4/E4,NA())
A5: =municipal!A5 | B5: =municipal!B5 | C5: =municipal!E5 | D5: =municipal!I5 | E5: =municipal!J5 | F5: =municipal!K5 | G5: =IF(AND(ISNUMBER(F5),ISNUMBER(D5),D5>0),F5/D5*100,NA()) | H5: =IF(AND(ISNUMBER(C5),ISNUMBER(E5),E5>0),C5/E5,NA())
A6: =municipal!A6 | B6: =municipal!B6 | C6: =municipal!E6 | D6: =municipal!I6 | E6: =municipal!J6 | F6: =municipal!K6 | G6: =IF(AND(ISNUMBER(F6),ISNUMBER(D6),D6>0),F6/D6*100,NA()) | H6: =IF(AND(ISNUMBER(C6),ISNUMBER(E6),E6>0),C6/E6,NA())
A7: =municipal!A7 | B7: =municipal!B7 | C7: =municipal!E7 | D7: =municipal!I7 | E7: =municipal!J7 | F7: =municipal!K7 | G7: =IF(AND(ISNUMBER(F7),ISNUMBER(D7),D7>0),F7/D7*100,NA()) | H7: =IF(AND(ISNUMBER(C7),ISNUMBER(E7),E7>0),C7/E7,NA())
A8: =municipal!A8 | B8: =municipal!B8 | C8: =municipal!E8 | D8: =municipal!I8 | E8: =municipal!J8 | F8: =municipal!K8 | G8: =IF(AND(ISNUMBER(F8),ISNUMBER(D8),D8>0),F8/D8*100,NA()) | H8: =IF(AND(ISNUMBER(C8),ISNUMBER(E8),E8>0),C8/E8,NA())
A9: =municipal!A9 | B9: =municipal!B9 | C9: =municipal!E9 | D9: =municipal!I9 | E9: =municipal!J9 | F9: =municipal!K9 | G9: =IF(AND(ISNUMBER(F9),ISNUMBER(D9),D9>0),F9/D9*100,NA()) | H9: =IF(AND(ISNUMBER(C9),ISNUMBER(E9),E9>0),C9/E9,NA())
A10: =municipal!A10 | B10: =municipal!B10 | C10: =municipal!E10 | D10: =municipal!I10 | E10: =municipal!J10 | F10: =municipal!K10 | G10: =IF(AND(ISNUMBER(F10),ISNUMBER(D10),D10>0),F10/D10*100,NA()) | H10: =IF(AND(ISNUMBER(C10),ISNUMBER(E10),E10>0),C10/E10,NA())
A11: =municipal!A11 | B11: =municipal!B11 | C11: =municipal!E11 | D11: =municipal!I11 | E11: =municipal!J11 | F11: =municipal!K11 | G11: =IF(AND(ISNUMBER(F11),ISNUMBER(D11),D11>0),F11/D11*100,NA()) | H11: =IF(AND(ISNUMBER(C11),ISNUMBER(E11),E11>0),C11/E11,NA())
A12: =municipal!A12 | B12: =municipal!B12 | C12: =municipal!E12 | D12: =municipal!I12 | E12: =municipal!J12 | F12: =municipal!K12 | G12: =IF(AND(ISNUMBER(F12),ISNUMBER(D12),D12>0),F12/D12*100,NA()) | H12: =IF(AND(ISNUMBER(C12),ISNUMBER(E12),E12>0),C12/E12,NA())
A13: =municipal!A13 | B13: =municipal!B13 | C13: =municipal!E13 | D13: =municipal!I13 | E13: =municipal!J13 | F13: =municipal!K13 | G13: =IF(AND(ISNUMBER(F13),ISNUMBER(D13),D13>0),F13/D13*100,NA()) | H13: =IF(AND(ISNUMBER(C13),ISNUMBER(E13),E13>0),C13/E13,NA())
... A23: =municipal!A23 | B23: =municipal!B23 | C23: =municipal!E23 | D23: =municipal!I23 | E23: =municipal!J23 | F23: =municipal!K23 | G23: =IF(AND(ISNUMBER(F23),ISNUMBER(D23),D23>0),F23/D23*100,NA()) | H23: =IF(AND(ISNUMBER(C23),ISNUMBER(E23),E23>0),C23/E23,NA())

Sheet indicators_summary
A1: indicator | B1: numerator_total | C1: denominator_total | D1: scale_factor | E1: aggregate_value | F1: unit
A2: county_population_total | B2: =SUM(indicators_demography!C2:C23) | D2: 1 | E2: =B2 | F2: persones
A3: county_housing_total | B3: =SUM(indicators_housing!D2:D23) | D3: 1 | E3: =B3 | F3: habitatges
A4: county_population_0_14_pct | B4: =SUM(indicators_demography!D2:D23) | C4: =SUM(indicators_demography!C2:C23) | D4: 100 | E4: =IF(C4>0,B4/C4*D4,NA()) | F4: %
A5: county_population_65_plus_pct | B5: =SUM(indicators_demography!E2:E23) | C5: =SUM(indicators_demography!C2:C23) | D5: 100 | E5: =IF(C5>0,B5/C5*D5,NA()) | F5: %
A6: county_ageing_index | B6: =SUM(indicators_demography!E2:E23) | C6: =SUM(indicators_demography!D2:D23) | D6: 100 | E6: =IF(C6>0,B6/C6*D6,NA()) | F6: persones de 65+ per 100 de 0–14
A7: county_population_density | B7: =SUM(indicators_demography!C2:C23) | C7: =SUM(indicators_demography!F2:F23) | D7: 1 | E7: =IF(C7>0,B7/C7,NA()) | F7: habitants/km²
A8: county_housing_non_main_pct | B8: =SUM(indicators_housing!F2:F23) | C8: =SUM(indicators_housing!D2:D23) | D8: 100 | E8: =IF(C8>0,B8/C8*D8,NA()) | F8: %
A9: county_residents_per_housing_main | B9: =SUM(indicators_housing!C2:C23) | C9: =SUM(indicators_housing!E2:E23) | D9: 1 | E9: =IF(C9>0,B9/C9,NA()) | F9: residents/habitatge principal

Sheet source_population_time
A1: year | B1: municipality_code | C1: municipality | D1: population | E1: table_id | F1: source | G1: source_url
A2: 2000 | B2: 431711 | C2: Vila-seca | D2: 13133 | E2: 1063 | F2: Idescat, a partir del Padró continu de l'INE. | G2: https://api.idescat.cat/taules/v2/pmh/1180/1063/mun/data?lang=ca&MUN=431711&SEX=TOTAL&AGE=TOTAL
A3: 2001 | B3: 431711 | C3: Vila-seca | D3: 13420.0 | E3: 1063 | F3: Idescat, a partir del Padró continu de l'INE. | G3: https://api.idescat.cat/taules/v2/pmh/1180/1063/mun/data?lang=ca&MUN=431711&SEX=TOTAL&AGE=TOTAL
A4: 2002 | B4: 431711 | C4: Vila-seca | D4: 13927 | E4: 1063 | F4: Idescat, a partir del Padró continu de l'INE. | G4: https://api.idescat.cat/taules/v2/pmh/1180/1063/mun/data?lang=ca&MUN=431711&SEX=TOTAL&AGE=TOTAL
A5: 2003 | B5: 431711 | C5: Vila-seca | D5: 14377 | E5: 1063 | F5: Idescat, a partir del Padró continu de l'INE. | G5: https://api.idescat.cat/taules/v2/pmh/1180/1063/mun/data?lang=ca&MUN=431711&SEX=TOTAL&AGE=TOTAL
A6: 2004 | B6: 431711 | C6: Vila-seca | D6: 14998 | E6: 1063 | F6: Idescat, a partir del Padró continu de l'INE. | G6: https://api.idescat.cat/taules/v2/pmh/1180/1063/mun/data?lang=ca&MUN=431711&SEX=TOTAL&AGE=TOTAL
A7: 2005 | B7: 431711 | C7: Vila-seca | D7: 15875 | E7: 1063 | F7: Idescat, a partir del Padró continu de l'INE. | G7: https://api.idescat.cat/taules/v2/pmh/1180/1063/mun/data?lang=ca&MUN=431711&SEX=TOTAL&AGE=TOTAL
A8: 2006 | B8: 431711 | C8: Vila-seca | D8: 17305 | E8: 1063 | F8: Idescat, a partir del Padró continu de l'INE. | G8: https://api.idescat.cat/taules/v2/pmh/1180/1063/mun/data?lang=ca&MUN=431711&SEX=TOTAL&AGE=TOTAL
A9: 2007 | B9: 431711 | C9: Vila-seca | D9: 18678 | E9: 1063 | F9: Idescat, a partir del Padró continu de l'INE. | G9: https://api.idescat.cat/taules/v2/pmh/1180/1063/mun/data?lang=ca&MUN=431711&SEX=TOTAL&AGE=TOTAL
A10: 2008 | B10: 431711 | C10: Vila-seca | D10: 20039 | E10: 1063 | F10: Idescat, a partir del Padró continu de l'INE. | G10: https://api.idescat.cat/taules/v2/pmh/1180/1063/mun/data?lang=ca&MUN=431711&SEX=TOTAL&AGE=TOTAL
A11: 2009 | B11: 431711 | C11: Vila-seca | D11: 20866 | E11: 1063 | F11: Idescat, a partir del Padró continu de l'INE. | G11: https://api.idescat.cat/taules/v2/pmh/1180/1063/mun/data?lang=ca&MUN=431711&SEX=TOTAL&AGE=TOTAL
A12: 2010 | B12: 431711 | C12: Vila-seca | D12: 21373 | E12: 1063 | F12: Idescat, a partir del Padró continu de l'INE. | G12: https://api.idescat.cat/taules/v2/pmh/1180/1063/mun/data?lang=ca&MUN=431711&SEX=TOTAL&AGE=TOTAL
... A24: 2022 | B24: 431711 | C24: Vila-seca | D24: 22681 | E24: 8078 | F24: Idescat, a partir del Padró continu de l'INE. | G24: https://api.idescat.cat/taules/v2/pmh/1180/8078/mun/data?lang=ca&MUN=431711&SEX=TOTAL&AGE=TOTAL

Sheet prepared_population_time
A1: Any | B1: Població | C1: Canvi anual | D1: Canvi anual (%) | E1: Etiqueta biennal
A2: 2000 | B2: 13133 | E2: =IF(OR(MOD(A2,2)=0,A2=2022),A2,"")
A3: 2001 | B3: 13420 | C3: =B3-B2 | D3: =IF(B2>0,(B3/B2-1)*100,NA()) | E3: =IF(OR(MOD(A3,2)=0,A3=2022),A3,"")
A4: 2002 | B4: 13927 | C4: =B4-B3 | D4: =IF(B3>0,(B4/B3-1)*100,NA()) | E4: =IF(OR(MOD(A4,2)=0,A4=2022),A4,"")
A5: 2003 | B5: 14377 | C5: =B5-B4 | D5: =IF(B4>0,(B5/B4-1)*100,NA()) | E5: =IF(OR(MOD(A5,2)=0,A5=2022),A5,"")
A6: 2004 | B6: 14998 | C6: =B6-B5 | D6: =IF(B5>0,(B6/B5-1)*100,NA()) | E6: =IF(OR(MOD(A6,2)=0,A6=2022),A6,"")
A7: 2005 | B7: 15875 | C7: =B7-B6 | D7: =IF(B6>0,(B7/B6-1)*100,NA()) | E7: =IF(OR(MOD(A7,2)=0,A7=2022),A7,"")
A8: 2006 | B8: 17305 | C8: =B8-B7 | D8: =IF(B7>0,(B8/B7-1)*100,NA()) | E8: =IF(OR(MOD(A8,2)=0,A8=2022),A8,"")
A9: 2007 | B9: 18678 | C9: =B9-B8 | D9: =IF(B8>0,(B9/B8-1)*100,NA()) | E9: =IF(OR(MOD(A9,2)=0,A9=2022),A9,"")
A10: 2008 | B10: 20039 | C10: =B10-B9 | D10: =IF(B9>0,(B10/B9-1)*100,NA()) | E10: =IF(OR(MOD(A10,2)=0,A10=2022),A10,"")
A11: 2009 | B11: 20866 | C11: =B11-B10 | D11: =IF(B10>0,(B11/B10-1)*100,NA()) | E11: =IF(OR(MOD(A11,2)=0,A11=2022),A11,"")
A12: 2010 | B12: 21373 | C12: =B12-B11 | D12: =IF(B11>0,(B12/B11-1)*100,NA()) | E12: =IF(OR(MOD(A12,2)=0,A12=2022),A12,"")
A13: 2011 | B13: 21839 | C13: =B13-B12 | D13: =IF(B12>0,(B13/B12-1)*100,NA()) | E13: =IF(OR(MOD(A13,2)=0,A13=2022),A13,"")
A14: 2012 | B14: 22052 | C14: =B14-B13 | D14: =IF(B13>0,(B14/B13-1)*100,NA()) | E14: =IF(OR(MOD(A14,2)=0,A14=2022),A14,"")
... A24: 2022 | B24: 22681 | C24: =B24-B23 | D24: =IF(B23>0,(B24/B23-1)*100,NA()) | E24: =IF(OR(MOD(A24,2)=0,A24=2022),A24,"")

